<mujoco model="hopper">
  <compiler angle="radian" inertiafromgeom="true"/>
  <option integrator="RK4" timestep="0.01"/>
  <default>
  </default>
  
  <visual>
  </visual>

  <asset>
    <texture type="skybox" builtin="gradient" rgb1=".29 .0 .5" rgb2="0 0 0" width="100" height="100"/>
  </asset>

  <worldbody>
    <light cutoff="100" diffuse="1 1 1" dir="-0 0 -1.3" directional="true" exponent="1" pos="0 0 1.3" specular=".1 .1 .1"/>
    <geom name="part1" fromto="-1 0 0 -1 0 1" size="0.05" type="capsule"/>
    <camera name="track" mode="fixed" pos="-1 -3 1" xyaxes="1 0 0 0 0 1"/>
    <body name="main" pos="-1 0 1">
      <joint axis="0 -1 0" name="passive_joint" pos="0 0 0" range="-3 3" type="hinge"/>
      <geom name="part2" fromto="0 0 0 0 0 1" size="0.05" type="capsule" contype="3" conaffinity="3"/>
    </body>

    <body name="horizontal_finger" pos="0 0 0">
      <joint axis="1 0 0" name="horizontal_finger" pos="0 0 0" type="slide"/>
      <geom fromto="-2 0 2 -1.5 0 2" size="0.05" type="capsule" contype="1" conaffinity="1" rgba="0.8 0.6 .4 1"/>
    </body>

    <body name="vertical_finger" pos="0 0 0">
      <joint axis="0 0 -1" name="vertical_finger" pos="0 0 0" type="slide"/>
      <geom fromto="-1.75 0 2.5 -1.75 0 2" size="0.05" type="capsule" contype="2" conaffinity="2" rgba="0.8 0.6 .4 1"/>
    </body>

  </worldbody>

  <actuator>
    <position name="positionActuator1" kp="10" kv="4" joint="horizontal_finger"/>
    <position name="positionActuator2" kp="500" kv="100" joint="vertical_finger"/>
  </actuator>

</mujoco>